{
 "cells": [
  {
   "cell_type": "code",
   "execution_count": 1,
   "id": "6ca69744",
   "metadata": {},
   "outputs": [],
   "source": [
    "import os\n",
    "import numpy as np\n",
    "import tensorflow as tf"
   ]
  },
  {
   "cell_type": "code",
   "execution_count": 2,
   "id": "50e45eb5",
   "metadata": {},
   "outputs": [],
   "source": [
    "from tensorflow import keras"
   ]
  },
  {
   "cell_type": "code",
   "execution_count": 4,
   "id": "b1a41dbf",
   "metadata": {},
   "outputs": [
    {
     "name": "stdout",
     "output_type": "stream",
     "text": [
      "Requirement already satisfied: pyyaml in c:\\users\\user\\.conda\\envs\\tensorflow\\lib\\site-packages (6.0)\n",
      "Requirement already satisfied: h5py in c:\\users\\user\\.conda\\envs\\tensorflow\\lib\\site-packages (3.6.0)\n",
      "Requirement already satisfied: numpy>=1.14.5 in c:\\users\\user\\.conda\\envs\\tensorflow\\lib\\site-packages (from h5py) (1.21.5)\n",
      "Note: you may need to restart the kernel to use updated packages.\n"
     ]
    }
   ],
   "source": [
    "pip install pyyaml h5py"
   ]
  },
  {
   "cell_type": "code",
   "execution_count": 5,
   "id": "5ea09ada",
   "metadata": {},
   "outputs": [
    {
     "name": "stdout",
     "output_type": "stream",
     "text": [
      "Requirement already satisfied: matplotlib in c:\\users\\user\\.conda\\envs\\tensorflow\\lib\\site-packages (3.5.1)\n",
      "Requirement already satisfied: python-dateutil>=2.7 in c:\\users\\user\\.conda\\envs\\tensorflow\\lib\\site-packages (from matplotlib) (2.8.2)\n",
      "Requirement already satisfied: packaging>=20.0 in c:\\users\\user\\.conda\\envs\\tensorflow\\lib\\site-packages (from matplotlib) (21.3)\n",
      "Requirement already satisfied: cycler>=0.10 in c:\\users\\user\\.conda\\envs\\tensorflow\\lib\\site-packages (from matplotlib) (0.11.0)\n",
      "Requirement already satisfied: numpy>=1.17 in c:\\users\\user\\.conda\\envs\\tensorflow\\lib\\site-packages (from matplotlib) (1.21.5)\n",
      "Requirement already satisfied: kiwisolver>=1.0.1 in c:\\users\\user\\.conda\\envs\\tensorflow\\lib\\site-packages (from matplotlib) (1.4.2)\n",
      "Requirement already satisfied: pillow>=6.2.0 in c:\\users\\user\\.conda\\envs\\tensorflow\\lib\\site-packages (from matplotlib) (9.1.0)\n",
      "Requirement already satisfied: pyparsing>=2.2.1 in c:\\users\\user\\.conda\\envs\\tensorflow\\lib\\site-packages (from matplotlib) (3.0.4)\n",
      "Requirement already satisfied: fonttools>=4.22.0 in c:\\users\\user\\.conda\\envs\\tensorflow\\lib\\site-packages (from matplotlib) (4.32.0)\n",
      "Requirement already satisfied: six>=1.5 in c:\\users\\user\\.conda\\envs\\tensorflow\\lib\\site-packages (from python-dateutil>=2.7->matplotlib) (1.16.0)\n",
      "Note: you may need to restart the kernel to use updated packages.\n"
     ]
    }
   ],
   "source": [
    "pip install matplotlib"
   ]
  },
  {
   "cell_type": "code",
   "execution_count": 6,
   "id": "75e68b05",
   "metadata": {},
   "outputs": [],
   "source": [
    "from tensorflow import keras\n",
    "import matplotlib.pyplot as plt\n",
    "import PIL\n",
    "from tensorflow.keras import layers\n",
    "from tensorflow.keras.models import Sequential"
   ]
  },
  {
   "cell_type": "code",
   "execution_count": 7,
   "id": "14714e23",
   "metadata": {},
   "outputs": [
    {
     "ename": "OSError",
     "evalue": "SavedModel file does not exist at: C:/Users/User/Desktop/Tugas Akhir/filecnn.h5\\{saved_model.pbtxt|saved_model.pb}",
     "output_type": "error",
     "traceback": [
      "\u001b[1;31m---------------------------------------------------------------------------\u001b[0m",
      "\u001b[1;31mOSError\u001b[0m                                   Traceback (most recent call last)",
      "Input \u001b[1;32mIn [7]\u001b[0m, in \u001b[0;36m<cell line: 1>\u001b[1;34m()\u001b[0m\n\u001b[1;32m----> 1\u001b[0m model \u001b[38;5;241m=\u001b[39m \u001b[43mkeras\u001b[49m\u001b[38;5;241;43m.\u001b[39;49m\u001b[43mmodels\u001b[49m\u001b[38;5;241;43m.\u001b[39;49m\u001b[43mload_model\u001b[49m\u001b[43m(\u001b[49m\u001b[38;5;124;43m'\u001b[39;49m\u001b[38;5;124;43mC:/Users/User/Desktop/Tugas Akhir/filecnn.h5\u001b[39;49m\u001b[38;5;124;43m'\u001b[39;49m\u001b[43m)\u001b[49m\n",
      "File \u001b[1;32m~\\.conda\\envs\\tensorflow\\lib\\site-packages\\keras\\saving\\save.py:205\u001b[0m, in \u001b[0;36mload_model\u001b[1;34m(filepath, custom_objects, compile, options)\u001b[0m\n\u001b[0;32m    203\u001b[0m       filepath \u001b[38;5;241m=\u001b[39m path_to_string(filepath)\n\u001b[0;32m    204\u001b[0m       \u001b[38;5;28;01mif\u001b[39;00m \u001b[38;5;28misinstance\u001b[39m(filepath, \u001b[38;5;28mstr\u001b[39m):\n\u001b[1;32m--> 205\u001b[0m         \u001b[38;5;28;01mreturn\u001b[39;00m \u001b[43msaved_model_load\u001b[49m\u001b[38;5;241;43m.\u001b[39;49m\u001b[43mload\u001b[49m\u001b[43m(\u001b[49m\u001b[43mfilepath\u001b[49m\u001b[43m,\u001b[49m\u001b[43m \u001b[49m\u001b[38;5;28;43mcompile\u001b[39;49m\u001b[43m,\u001b[49m\u001b[43m \u001b[49m\u001b[43moptions\u001b[49m\u001b[43m)\u001b[49m\n\u001b[0;32m    207\u001b[0m \u001b[38;5;28;01mraise\u001b[39;00m \u001b[38;5;167;01mIOError\u001b[39;00m(\n\u001b[0;32m    208\u001b[0m     \u001b[38;5;124m'\u001b[39m\u001b[38;5;124mUnable to load model. Filepath is not an hdf5 file (or h5py is not \u001b[39m\u001b[38;5;124m'\u001b[39m\n\u001b[0;32m    209\u001b[0m     \u001b[38;5;124m'\u001b[39m\u001b[38;5;124mavailable) or SavedModel.\u001b[39m\u001b[38;5;124m'\u001b[39m)\n",
      "File \u001b[1;32m~\\.conda\\envs\\tensorflow\\lib\\site-packages\\keras\\saving\\saved_model\\load.py:108\u001b[0m, in \u001b[0;36mload\u001b[1;34m(path, compile, options)\u001b[0m\n\u001b[0;32m    103\u001b[0m \u001b[38;5;66;03m# TODO(kathywu): Add saving/loading of optimizer, compiled losses and metrics.\u001b[39;00m\n\u001b[0;32m    104\u001b[0m \u001b[38;5;66;03m# TODO(kathywu): Add code to load from objects that contain all endpoints\u001b[39;00m\n\u001b[0;32m    105\u001b[0m \n\u001b[0;32m    106\u001b[0m \u001b[38;5;66;03m# Look for metadata file or parse the SavedModel\u001b[39;00m\n\u001b[0;32m    107\u001b[0m metadata \u001b[38;5;241m=\u001b[39m saved_metadata_pb2\u001b[38;5;241m.\u001b[39mSavedMetadata()\n\u001b[1;32m--> 108\u001b[0m meta_graph_def \u001b[38;5;241m=\u001b[39m \u001b[43mtf\u001b[49m\u001b[38;5;241;43m.\u001b[39;49m\u001b[43m__internal__\u001b[49m\u001b[38;5;241;43m.\u001b[39;49m\u001b[43msaved_model\u001b[49m\u001b[38;5;241;43m.\u001b[39;49m\u001b[43mparse_saved_model\u001b[49m\u001b[43m(\u001b[49m\u001b[43mpath\u001b[49m\u001b[43m)\u001b[49m\u001b[38;5;241m.\u001b[39mmeta_graphs[\u001b[38;5;241m0\u001b[39m]\n\u001b[0;32m    109\u001b[0m object_graph_def \u001b[38;5;241m=\u001b[39m meta_graph_def\u001b[38;5;241m.\u001b[39mobject_graph_def\n\u001b[0;32m    110\u001b[0m path_to_metadata_pb \u001b[38;5;241m=\u001b[39m os\u001b[38;5;241m.\u001b[39mpath\u001b[38;5;241m.\u001b[39mjoin(path, constants\u001b[38;5;241m.\u001b[39mSAVED_METADATA_PATH)\n",
      "File \u001b[1;32m~\\.conda\\envs\\tensorflow\\lib\\site-packages\\tensorflow\\python\\saved_model\\loader_impl.py:118\u001b[0m, in \u001b[0;36mparse_saved_model\u001b[1;34m(export_dir)\u001b[0m\n\u001b[0;32m    116\u001b[0m     \u001b[38;5;28;01mraise\u001b[39;00m \u001b[38;5;167;01mIOError\u001b[39;00m(\u001b[38;5;124m\"\u001b[39m\u001b[38;5;124mCannot parse file \u001b[39m\u001b[38;5;132;01m%s\u001b[39;00m\u001b[38;5;124m: \u001b[39m\u001b[38;5;132;01m%s\u001b[39;00m\u001b[38;5;124m.\u001b[39m\u001b[38;5;124m\"\u001b[39m \u001b[38;5;241m%\u001b[39m (path_to_pbtxt, \u001b[38;5;28mstr\u001b[39m(e)))\n\u001b[0;32m    117\u001b[0m \u001b[38;5;28;01melse\u001b[39;00m:\n\u001b[1;32m--> 118\u001b[0m   \u001b[38;5;28;01mraise\u001b[39;00m \u001b[38;5;167;01mIOError\u001b[39;00m(\n\u001b[0;32m    119\u001b[0m       \u001b[38;5;124m\"\u001b[39m\u001b[38;5;124mSavedModel file does not exist at: \u001b[39m\u001b[38;5;132;01m%s\u001b[39;00m\u001b[38;5;132;01m%s\u001b[39;00m\u001b[38;5;124m{\u001b[39m\u001b[38;5;132;01m%s\u001b[39;00m\u001b[38;5;124m|\u001b[39m\u001b[38;5;132;01m%s\u001b[39;00m\u001b[38;5;124m}\u001b[39m\u001b[38;5;124m\"\u001b[39m \u001b[38;5;241m%\u001b[39m\n\u001b[0;32m    120\u001b[0m       (export_dir, os\u001b[38;5;241m.\u001b[39mpath\u001b[38;5;241m.\u001b[39msep, constants\u001b[38;5;241m.\u001b[39mSAVED_MODEL_FILENAME_PBTXT,\n\u001b[0;32m    121\u001b[0m        constants\u001b[38;5;241m.\u001b[39mSAVED_MODEL_FILENAME_PB))\n",
      "\u001b[1;31mOSError\u001b[0m: SavedModel file does not exist at: C:/Users/User/Desktop/Tugas Akhir/filecnn.h5\\{saved_model.pbtxt|saved_model.pb}"
     ]
    }
   ],
   "source": [
    "model = keras.models.load_model('C:/Users/User/Desktop/Tugas Akhir/filecnn.h5')"
   ]
  },
  {
   "cell_type": "code",
   "execution_count": null,
   "id": "d5ab889a",
   "metadata": {},
   "outputs": [],
   "source": []
  }
 ],
 "metadata": {
  "kernelspec": {
   "display_name": "Python 3 (ipykernel)",
   "language": "python",
   "name": "python3"
  },
  "language_info": {
   "codemirror_mode": {
    "name": "ipython",
    "version": 3
   },
   "file_extension": ".py",
   "mimetype": "text/x-python",
   "name": "python",
   "nbconvert_exporter": "python",
   "pygments_lexer": "ipython3",
   "version": "3.9.12"
  }
 },
 "nbformat": 4,
 "nbformat_minor": 5
}
